[2023-05-02T08:43:46.181+0000] {taskinstance.py:1087} INFO - Dependencies all met for <TaskInstance: prueba_tecnica.transform_data manual__2023-05-02T08:43:34.737188+00:00 map_index=2 [queued]>
[2023-05-02T08:43:46.200+0000] {taskinstance.py:1087} INFO - Dependencies all met for <TaskInstance: prueba_tecnica.transform_data manual__2023-05-02T08:43:34.737188+00:00 map_index=2 [queued]>
[2023-05-02T08:43:46.200+0000] {taskinstance.py:1283} INFO - 
--------------------------------------------------------------------------------
[2023-05-02T08:43:46.206+0000] {taskinstance.py:1284} INFO - Starting attempt 1 of 1
[2023-05-02T08:43:46.207+0000] {taskinstance.py:1285} INFO - 
--------------------------------------------------------------------------------
[2023-05-02T08:43:46.231+0000] {taskinstance.py:1304} INFO - Executing <Mapped(_PythonDecoratedOperator): transform_data> on 2023-05-02 08:43:34.737188+00:00
[2023-05-02T08:43:46.239+0000] {standard_task_runner.py:55} INFO - Started process 569 to run task
[2023-05-02T08:43:46.249+0000] {standard_task_runner.py:82} INFO - Running: ['***', 'tasks', 'run', 'prueba_tecnica', 'transform_data', 'manual__2023-05-02T08:43:34.737188+00:00', '--job-id', '28', '--raw', '--subdir', 'DAGS_FOLDER/data_process/prueba/Prueba_Tecnica.py', '--cfg-path', '/tmp/tmpsn2mv3ju', '--map-index', '2']
[2023-05-02T08:43:46.253+0000] {standard_task_runner.py:83} INFO - Job 28: Subtask transform_data
[2023-05-02T08:43:46.368+0000] {task_command.py:389} INFO - Running <TaskInstance: prueba_tecnica.transform_data manual__2023-05-02T08:43:34.737188+00:00 map_index=2 [running]> on host fc43d9cc2362
[2023-05-02T08:43:46.708+0000] {taskinstance.py:1511} INFO - Exporting the following env vars:
AIRFLOW_CTX_DAG_OWNER=loliveros
AIRFLOW_CTX_DAG_ID=prueba_tecnica
AIRFLOW_CTX_TASK_ID=transform_data
AIRFLOW_CTX_EXECUTION_DATE=2023-05-02T08:43:34.737188+00:00
AIRFLOW_CTX_TRY_NUMBER=1
AIRFLOW_CTX_DAG_RUN_ID=manual__2023-05-02T08:43:34.737188+00:00
[2023-05-02T08:43:46.709+0000] {taskinstance.py:1772} ERROR - Task failed with exception
Traceback (most recent call last):
  File "/home/airflow/.local/lib/python3.9/site-packages/airflow/decorators/base.py", line 217, in execute
    return_value = super().execute(context)
  File "/home/airflow/.local/lib/python3.9/site-packages/airflow/operators/python.py", line 175, in execute
    return_value = self.execute_callable()
  File "/home/airflow/.local/lib/python3.9/site-packages/airflow/operators/python.py", line 192, in execute_callable
    return self.python_callable(*self.op_args, **self.op_kwargs)
  File "/opt/airflow/dags/data_process/prueba/Prueba_Tecnica.py", line 119, in transform_data
    log.info(f'Files downloaded: {str(files_csv_raw)}')
UnboundLocalError: local variable 'files_csv_raw' referenced before assignment
[2023-05-02T08:43:46.719+0000] {taskinstance.py:1322} INFO - Marking task as FAILED. dag_id=prueba_tecnica, task_id=transform_data, map_index=2, execution_date=20230502T084334, start_date=20230502T084346, end_date=20230502T084346
[2023-05-02T08:43:46.731+0000] {standard_task_runner.py:100} ERROR - Failed to execute job 28 for task transform_data (local variable 'files_csv_raw' referenced before assignment; 569)
[2023-05-02T08:43:46.781+0000] {local_task_job.py:159} INFO - Task exited with return code 1
[2023-05-02T08:43:46.797+0000] {taskinstance.py:2582} INFO - 0 downstream tasks scheduled from follow-on schedule check
